Workbook

Sheet Assumptions
A1: FINANCIAL MODEL — Teen Sleepwear DTC Brand (Illustrative)
A2: HOW TO USE: Edit any blue cell (yellow background) to update the model. All other cells are formulas and recalculate automatically.
A3: COLOUR KEY: Blue text = editable input | Black text = formula | Green text = cross-sheet reference
A4: TABS: Assumptions → Unit Economics → 3-Year P&L → Break-Even
A6: PRODUCT PRICING (£ GBP)
A7: Product | B7: Lower Price (£) | C7: Higher Price (£)
A8: PJ Set | B8: 35 | C8: 45
A9: Lounge Set | B9: 38 | C9: 48
A10: Shorts Set | B10: 30 | C10: 38
A12: COST OF GOODS SOLD (£ per unit)
A13: Product | B13: POD COGS (£) | C13: Direct COGS (£)
A14: PJ Set | B14: 27 | C14: 12
A15: Lounge Set | B15: 25 | C15: 11
A16: Shorts Set | B16: 18 | C16: 8
A18: Source: POD costs from Printful/Printify benchmarks (Mar 2026)
A19: Source: Direct mfg costs are industry estimates — see methodology note in notebook 06
A21: ANNUAL FIXED COSTS (£)
A22: Cost Item | B22: POD Model (£) | C22: Direct Model (£)
A23: Shopify + apps | B23: 312 | C23: 312
A24: Photography / content | B24: 800 | C24: 1200
A25: Marketing (organic + paid) | B25: 1500 | C25: 2500
A26: Domain + email | B26: 30 | C26: 30
A27: Samples + R&D | B27: 300 | C27: 500
A28: Initial inventory (Year 1 only) | B28: 0 | C28: 5000
A29: Warehousing / 3PL | B29: 0 | C29: 1200
A30: TOTAL FIXED COSTS (Year 1) | B30: =SUM(B23:B29) -> 2942 | C30: =SUM(C23:C29) -> 10742
A31: TOTAL FIXED COSTS (Year 2+) | B31: =SUM(B23:B27) -> 2942 | C31: =SUM(C23:C27,C29) -> 5742
A33: VOLUME ASSUMPTIONS (orders/year)
A34: Scenario | B34: Year 1 | C34: Year 2 | D34: Year 3 | E34: Y1→Y2 Growth | F34: Y2→Y3 Growth
A35: Conservative | B35: 100 | C35: 175 | D35: 260 | E35: =(C35-B35)/B35 -> 0.75 | F35: =(D35-C35)/C35 -> 0.48571429
A36: Base | B36: 250 | C36: 450 | D36: 700 | E36: =(C36-B36)/B36 -> 0.8 | F36: =(D36-C36)/C36 -> 0.55555556
A37: Optimistic | B37: 500 | C37: 1000 | D37: 1750 | E37: =(C37-B37)/B37 -> 1 | F37: =(D37-C37)/C37 -> 0.75
A39: PRODUCT MIX (% of total orders)
A40: PJ Set | B40: 0.45
A41: Lounge Set | B41: 0.3
A42: Shorts Set | B42: 0.25
A44: SOURCES
A45: DTC failure rates: ~90% close by year 5, ~30% in year 1, ~70% by year 3 (One Fourth, via inBeat Agency)
A46: Successful clothing startups aim for £1–10M revenue in first 3–5 years (BusinessDojo)
A47: UK fashion e-commerce CAGR ~10–15% (BoF/McKinsey; IRP Commerce)
...

Sheet Unit Economics
A1: UNIT ECONOMICS — POD vs Direct Manufacturing
A3: LOWER PRICE SCENARIO
A4: Product | B4: Price (£) | C4: POD COGS | D4: POD GP (£) | E4: POD Margin | F4: Direct COGS | G4: Direct GP (£) | H4: Direct Margin
A5: PJ Set | B5: =Assumptions!B8 -> 35 | C5: =Assumptions!B14 -> 27 | D5: =B5-C5 -> 8 | E5: =D5/B5 -> 0.22857143 | F5: =Assumptions!C14 -> 12 | G5: =B5-F5 -> 23 | H5: =G5/B5 -> 0.65714286
A6: Lounge Set | B6: =Assumptions!B9 -> 38 | C6: =Assumptions!B15 -> 25 | D6: =B6-C6 -> 13 | E6: =D6/B6 -> 0.34210526 | F6: =Assumptions!C15 -> 11 | G6: =B6-F6 -> 27 | H6: =G6/B6 -> 0.71052632
A7: Shorts Set | B7: =Assumptions!B10 -> 30 | C7: =Assumptions!B16 -> 18 | D7: =B7-C7 -> 12 | E7: =D7/B7 -> 0.4 | F7: =Assumptions!C16 -> 8 | G7: =B7-F7 -> 22 | H7: =G7/B7 -> 0.73333333
A10: HIGHER PRICE SCENARIO
A11: Product | B11: Price (£) | C11: POD COGS | D11: POD GP (£) | E11: POD Margin | F11: Direct COGS | G11: Direct GP (£) | H11: Direct Margin
A12: PJ Set | B12: =Assumptions!C8 -> 45 | C12: =Assumptions!B14 -> 27 | D12: =B12-C12 -> 18 | E12: =D12/B12 -> 0.4 | F12: =Assumptions!C14 -> 12 | G12: =B12-F12 -> 33 | H12: =G12/B12 -> 0.73333333
A13: Lounge Set | B13: =Assumptions!C9 -> 48 | C13: =Assumptions!B15 -> 25 | D13: =B13-C13 -> 23 | E13: =D13/B13 -> 0.47916667 | F13: =Assumptions!C15 -> 11 | G13: =B13-F13 -> 37 | H13: =G13/B13 -> 0.77083333
A14: Shorts Set | B14: =Assumptions!C10 -> 38 | C14: =Assumptions!B16 -> 18 | D14: =B14-C14 -> 20 | E14: =D14/B14 -> 0.52631579 | F14: =Assumptions!C16 -> 8 | G14: =B14-F14 -> 30 | H14: =G14/B14 -> 0.78947368

Sheet 3-Year P&L
A1: 3-YEAR P&L — BASE CASE
A3: POD — LOWER PRICE
B4: Year 1 | C4: Year 2 | D4: Year 3
A5: Orders | B5: =Assumptions!B36 -> 250 | C5: =Assumptions!C36 -> 450 | D5: =Assumptions!D36 -> 700
A6: Revenue | B6: =B5*(Assumptions!B40*Assumptions!B8+Assumptions!B41*Assumptions!B9+Assumptions!B42*Assumptions!B10) -> 8662.5 | C6: =C5*(Assumptions!B40*Assumptions!B8+Assumptions!B41*Assumptions!B9+Assumptions!B42*Assumptions!B10) -> 15592.5 | D6: =D5*(Assumptions!B40*Assumptions!B8+Assumptions!B41*Assumptions!B9+Assumptions!B42*Assumptions!B10) -> 24255
A7: COGS | B7: =B5*(Assumptions!B40*Assumptions!B14+Assumptions!B41*Assumptions!B15+Assumptions!B42*Assumptions!B16) -> 6037.5 | C7: =C5*(Assumptions!B40*Assumptions!B14+Assumptions!B41*Assumptions!B15+Assumptions!B42*Assumptions!B16) -> 10867.5 | D7: =D5*(Assumptions!B40*Assumptions!B14+Assumptions!B41*Assumptions!B15+Assumptions!B42*Assumptions!B16) -> 16905
A8: Gross Profit | B8: =B6-B7 -> 2625 | C8: =C6-C7 -> 4725 | D8: =D6-D7 -> 7350
A9: Gross Margin % | B9: =IF(B6=0,0,B8/B6) -> 0.3030303 | C9: =IF(C6=0,0,C8/C6) -> 0.3030303 | D9: =IF(D6=0,0,D8/D6) -> 0.3030303
A10: Fixed Costs | B10: =Assumptions!B30 -> 2942 | C10: =Assumptions!B31 -> 2942 | D10: =Assumptions!B31 -> 2942
A11: Net Profit | B11: =B8-B10 -> -317 | C11: =C8-C10 -> 1783 | D11: =D8-D10 -> 4408
A14: DIRECT — LOWER PRICE
B15: Year 1 | C15: Year 2 | D15: Year 3
A16: Orders | B16: =Assumptions!B36 -> 250 | C16: =Assumptions!C36 -> 450 | D16: =Assumptions!D36 -> 700
A17: Revenue | B17: =B16*(Assumptions!B40*Assumptions!B8+Assumptions!B41*Assumptions!B9+Assumptions!B42*Assumptions!B10) -> 8662.5 | C17: =C16*(Assumptions!B40*Assumptions!B8+Assumptions!B41*Assumptions!B9+Assumptions!B42*Assumptions!B10) -> 15592.5 | D17: =D16*(Assumptions!B40*Assumptions!B8+Assumptions!B41*Assumptions!B9+Assumptions!B42*Assumptions!B10) -> 24255
A18: COGS | B18: =B16*(Assumptions!B40*Assumptions!C14+Assumptions!B41*Assumptions!C15+Assumptions!B42*Assumptions!C16) -> 2675 | C18: =C16*(Assumptions!B40*Assumptions!C14+Assumptions!B41*Assumptions!C15+Assumptions!B42*Assumptions!C16) -> 4815 | D18: =D16*(Assumptions!B40*Assumptions!C14+Assumptions!B41*Assumptions!C15+Assumptions!B42*Assumptions!C16) -> 7490
A19: Gross Profit | B19: =B17-B18 -> 5987.5 | C19: =C17-C18 -> 10777.5 | D19: =D17-D18 -> 16765
A20: Gross Margin % | B20: =IF(B17=0,0,B19/B17) -> 0.69119769 | C20: =IF(C17=0,0,C19/C17) -> 0.69119769 | D20: =IF(D17=0,0,D19/D17) -> 0.69119769
A21: Fixed Costs | B21: =Assumptions!C30 -> 10742 | C21: =Assumptions!C31 -> 5742 | D21: =Assumptions!C31 -> 5742
A22: Net Profit | B22: =B19-B21 -> -4754.5 | C22: =C19-C21 -> 5035.5 | D22: =D19-D21 -> 11023
A25: POD — HIGHER PRICE
B26: Year 1 | C26: Year 2 | D26: Year 3
A27: Orders | B27: =Assumptions!B36 -> 250 | C27: =Assumptions!C36 -> 450 | D27: =Assumptions!D36 -> 700
A28: Revenue | B28: =B27*(Assumptions!B40*Assumptions!C8+Assumptions!B41*Assumptions!C9+Assumptions!B42*Assumptions!C10) -> 11037.5 | C28: =C27*(Assumptions!B40*Assumptions!C8+Assumptions!B41*Assumptions!C9+Assumptions!B42*Assumptions!C10) -> 19867.5 | D28: =D27*(Assumptions!B40*Assumptions!C8+Assumptions!B41*Assumptions!C9+Assumptions!B42*Assumptions!C10) -> 30905
A29: COGS | B29: =B27*(Assumptions!B40*Assumptions!B14+Assumptions!B41*Assumptions!B15+Assumptions!B42*Assumptions!B16) -> 6037.5 | C29: =C27*(Assumptions!B40*Assumptions!B14+Assumptions!B41*Assumptions!B15+Assumptions!B42*Assumptions!B16) -> 10867.5 | D29: =D27*(Assumptions!B40*Assumptions!B14+Assumptions!B41*Assumptions!B15+Assumptions!B42*Assumptions!B16) -> 16905
A30: Gross Profit | B30: =B28-B29 -> 5000 | C30: =C28-C29 -> 9000 | D30: =D28-D29 -> 14000
A31: Gross Margin % | B31: =IF(B28=0,0,B30/B28) -> 0.45300113 | C31: =IF(C28=0,0,C30/C28) -> 0.45300113 | D31: =IF(D28=0,0,D30/D28) -> 0.45300113
A32: Fixed Costs | B32: =Assumptions!B30 -> 2942 | C32: =Assumptions!B31 -> 2942 | D32: =Assumptions!B31 -> 2942
A33: Net Profit | B33: =B30-B32 -> 2058 | C33: =C30-C32 -> 6058 | D33: =D30-D32 -> 11058
A36: DIRECT — HIGHER PRICE
B37: Year 1 | C37: Year 2 | D37: Year 3
A38: Orders | B38: =Assumptions!B36 -> 250 | C38: =Assumptions!C36 -> 450 | D38: =Assumptions!D36 -> 700
A39: Revenue | B39: =B38*(Assumptions!B40*Assumptions!C8+Assumptions!B41*Assumptions!C9+Assumptions!B42*Assumptions!C10) -> 11037.5 | C39: =C38*(Assumptions!B40*Assumptions!C8+Assumptions!B41*Assumptions!C9+Assumptions!B42*Assumptions!C10) -> 19867.5 | D39: =D38*(Assumptions!B40*Assumptions!C8+Assumptions!B41*Assumptions!C9+Assumptions!B42*Assumptions!C10) -> 30905
A40: COGS | B40: =B38*(Assumptions!B40*Assumptions!C14+Assumptions!B41*Assumptions!C15+Assumptions!B42*Assumptions!C16) -> 2675 | C40: =C38*(Assumptions!B40*Assumptions!C14+Assumptions!B41*Assumptions!C15+Assumptions!B42*Assumptions!C16) -> 4815 | D40: =D38*(Assumptions!B40*Assumptions!C14+Assumptions!B41*Assumptions!C15+Assumptions!B42*Assumptions!C16) -> 7490
A41: Gross Profit | B41: =B39-B40 -> 8362.5 | C41: =C39-C40 -> 15052.5 | D41: =D39-D40 -> 23415
A42: Gross Margin % | B42: =IF(B39=0,0,B41/B39) -> 0.75764439 | C42: =IF(C39=0,0,C41/C39) -> 0.75764439 | D42: =IF(D39=0,0,D41/D39) -> 0.75764439
A43: Fixed Costs | B43: =Assumptions!C30 -> 10742 | C43: =Assumptions!C31 -> 5742 | D43: =Assumptions!C31 -> 5742
A44: Net Profit | B44: =B41-B43 -> -2379.5 | C44: =C41-C43 -> 9310.5 | D44: =D41-D43 -> 17673

Sheet Break-Even
A1: BREAK-EVEN ANALYSIS
A3: Model / Price | B3: Blended GP/Order (£) | C3: Y1 Fixed Costs (£) | D3: Break-Even Orders (Y1)
A4: POD — Lower | B4: =Assumptions!B40*(Assumptions!B8-Assumptions!B14)+Assumptions!B41*(Assumptions!B9-Assumptions!B15)+Assumptions!B42*(Assumptions!B10-Assumptions!B16) -> 10.5 | C4: =Assumptions!B30 -> 2942 | D4: =ROUNDUP(C4/B4,0) -> 281
A5: Direct — Lower | B5: =Assumptions!B40*(Assumptions!B8-Assumptions!C14)+Assumptions!B41*(Assumptions!B9-Assumptions!C15)+Assumptions!B42*(Assumptions!B10-Assumptions!C16) -> 23.95 | C5: =Assumptions!C30 -> 10742 | D5: =ROUNDUP(C5/B5,0) -> 449
A6: POD — Higher | B6: =Assumptions!B40*(Assumptions!C8-Assumptions!B14)+Assumptions!B41*(Assumptions!C9-Assumptions!B15)+Assumptions!B42*(Assumptions!C10-Assumptions!B16) -> 20 | C6: =Assumptions!B30 -> 2942 | D6: =ROUNDUP(C6/B6,0) -> 148
A7: Direct — Higher | B7: =Assumptions!B40*(Assumptions!C8-Assumptions!C14)+Assumptions!B41*(Assumptions!C9-Assumptions!C15)+Assumptions!B42*(Assumptions!C10-Assumptions!C16) -> 33.45 | C7: =Assumptions!C30 -> 10742 | D7: =ROUNDUP(C7/B7,0) -> 322
